nohup: ignoring input
ERROR:root:code for hash sha384 was not found.
Traceback (most recent call last):
  File "/home/liudefen/opt/python3.8.0/lib/python3.8/hashlib.py", line 251, in <module>
    globals()[__func_name] = __get_hash(__func_name)
  File "/home/liudefen/opt/python3.8.0/lib/python3.8/hashlib.py", line 120, in __get_builtin_constructor
    raise ValueError('unsupported hash type ' + name)
ValueError: unsupported hash type sha384
ERROR:root:code for hash sha512 was not found.
Traceback (most recent call last):
  File "/home/liudefen/opt/python3.8.0/lib/python3.8/hashlib.py", line 251, in <module>
    globals()[__func_name] = __get_hash(__func_name)
  File "/home/liudefen/opt/python3.8.0/lib/python3.8/hashlib.py", line 120, in __get_builtin_constructor
    raise ValueError('unsupported hash type ' + name)
ValueError: unsupported hash type sha512
ERROR:root:code for hash blake2b was not found.
Traceback (most recent call last):
  File "/home/liudefen/opt/python3.8.0/lib/python3.8/hashlib.py", line 251, in <module>
    globals()[__func_name] = __get_hash(__func_name)
  File "/home/liudefen/opt/python3.8.0/lib/python3.8/hashlib.py", line 120, in __get_builtin_constructor
    raise ValueError('unsupported hash type ' + name)
ValueError: unsupported hash type blake2b
ERROR:root:code for hash blake2s was not found.
Traceback (most recent call last):
  File "/home/liudefen/opt/python3.8.0/lib/python3.8/hashlib.py", line 251, in <module>
    globals()[__func_name] = __get_hash(__func_name)
  File "/home/liudefen/opt/python3.8.0/lib/python3.8/hashlib.py", line 120, in __get_builtin_constructor
    raise ValueError('unsupported hash type ' + name)
ValueError: unsupported hash type blake2s
ERROR:root:code for hash sha3_224 was not found.
Traceback (most recent call last):
  File "/home/liudefen/opt/python3.8.0/lib/python3.8/hashlib.py", line 251, in <module>
    globals()[__func_name] = __get_hash(__func_name)
  File "/home/liudefen/opt/python3.8.0/lib/python3.8/hashlib.py", line 120, in __get_builtin_constructor
    raise ValueError('unsupported hash type ' + name)
ValueError: unsupported hash type sha3_224
ERROR:root:code for hash sha3_256 was not found.
Traceback (most recent call last):
  File "/home/liudefen/opt/python3.8.0/lib/python3.8/hashlib.py", line 251, in <module>
    globals()[__func_name] = __get_hash(__func_name)
  File "/home/liudefen/opt/python3.8.0/lib/python3.8/hashlib.py", line 120, in __get_builtin_constructor
    raise ValueError('unsupported hash type ' + name)
ValueError: unsupported hash type sha3_256
ERROR:root:code for hash sha3_384 was not found.
Traceback (most recent call last):
  File "/home/liudefen/opt/python3.8.0/lib/python3.8/hashlib.py", line 251, in <module>
    globals()[__func_name] = __get_hash(__func_name)
  File "/home/liudefen/opt/python3.8.0/lib/python3.8/hashlib.py", line 120, in __get_builtin_constructor
    raise ValueError('unsupported hash type ' + name)
ValueError: unsupported hash type sha3_384
ERROR:root:code for hash sha3_512 was not found.
Traceback (most recent call last):
  File "/home/liudefen/opt/python3.8.0/lib/python3.8/hashlib.py", line 251, in <module>
    globals()[__func_name] = __get_hash(__func_name)
  File "/home/liudefen/opt/python3.8.0/lib/python3.8/hashlib.py", line 120, in __get_builtin_constructor
    raise ValueError('unsupported hash type ' + name)
ValueError: unsupported hash type sha3_512
ERROR:root:code for hash shake_128 was not found.
Traceback (most recent call last):
  File "/home/liudefen/opt/python3.8.0/lib/python3.8/hashlib.py", line 251, in <module>
    globals()[__func_name] = __get_hash(__func_name)
  File "/home/liudefen/opt/python3.8.0/lib/python3.8/hashlib.py", line 120, in __get_builtin_constructor
    raise ValueError('unsupported hash type ' + name)
ValueError: unsupported hash type shake_128
ERROR:root:code for hash shake_256 was not found.
Traceback (most recent call last):
  File "/home/liudefen/opt/python3.8.0/lib/python3.8/hashlib.py", line 251, in <module>
    globals()[__func_name] = __get_hash(__func_name)
  File "/home/liudefen/opt/python3.8.0/lib/python3.8/hashlib.py", line 120, in __get_builtin_constructor
    raise ValueError('unsupported hash type ' + name)
ValueError: unsupported hash type shake_256
Traceback (most recent call last):
  File "/home/liudefen/opt/python3.8.0/lib/python3.8/random.py", line 51, in <module>
    from _sha512 import sha512 as _sha512
ImportError: /home/liudefen/opt/python3.8.0/lib/python3.8/lib-dynload/_sha512.cpython-38-x86_64-linux-gnu.so: failed to map segment from shared object: Cannot allocate memory

During handling of the above exception, another exception occurred:

Traceback (most recent call last):
  File "bit_generator.pyx", line 40, in numpy.random.bit_generator
  File "/home/liudefen/opt/python3.8.0/lib/python3.8/secrets.py", line 20, in <module>
    from random import SystemRandom
  File "/home/liudefen/opt/python3.8.0/lib/python3.8/random.py", line 54, in <module>
    from hashlib import sha512 as _sha512
ImportError: cannot import name 'sha512' from 'hashlib' (/home/liudefen/opt/python3.8.0/lib/python3.8/hashlib.py)

During handling of the above exception, another exception occurred:

Traceback (most recent call last):
  File "/home/liudefen/opt/python3.8.0/lib/python3.8/random.py", line 51, in <module>
    from _sha512 import sha512 as _sha512
ImportError: /home/liudefen/opt/python3.8.0/lib/python3.8/lib-dynload/_sha512.cpython-38-x86_64-linux-gnu.so: failed to map segment from shared object: Cannot allocate memory

During handling of the above exception, another exception occurred:

Traceback (most recent call last):
  File "/home/liudefen/ecole-env/lib/python3.8/site-packages/numpy/__init__.py", line 161, in <module>
    from . import random
  File "/home/liudefen/ecole-env/lib/python3.8/site-packages/numpy/random/__init__.py", line 180, in <module>
    from . import _pickle
  File "/home/liudefen/ecole-env/lib/python3.8/site-packages/numpy/random/_pickle.py", line 1, in <module>
    from .mtrand import RandomState
  File "mtrand.pyx", line 1, in init numpy.random.mtrand
  File "bit_generator.pyx", line 43, in init numpy.random.bit_generator
  File "/home/liudefen/opt/python3.8.0/lib/python3.8/random.py", line 54, in <module>
    from hashlib import sha512 as _sha512
ImportError: cannot import name 'sha512' from 'hashlib' (/home/liudefen/opt/python3.8.0/lib/python3.8/hashlib.py)
Traceback (most recent call last):
  File "compute_evaluation_results.py", line 1, in <module>
    import ecole
  File "/home/liudefen/ecole-env/lib/python3.8/site-packages/ecole/__init__.py", line 3, in <module>
    from ecole.core import RandomEngine, seed, spawn_random_engine, Exception
ImportError: SystemError: <built-in method __contains__ of dict object at 0x7f7fdf3f6a40> returned a result with an error set
